Workbook

Sheet 견적서
A1: 견 적 서
A3: QUOTATION
A5: 견적번호 | B5: NMS-2610-KKT-01 | G5: 공 급 자 | H5: 상 호 | I5: 엔엠솔루션
A6: 견 적 일 | B6: 2026-10-12 | H6: 대 표 자 | I6: (인)
A7: 수 신 | B7: 금강변압기 유한회사 (KUMKANG TRANSFORMER) 귀중 | H7: 사업자번호
A8: 참 조 | H8: 주 소
A9: 공 사 명 | B9: 진공건조로 2분할체 회전·안착, 임시 베이스 제작, 접합부 사상·용접 공사 | H9: 연 락 처
A10: 공사 장소 | B10: 경기 화성시 마도면 마도공단로1길 214 사내 마당 | G10: (직인)
A11: 공사 기간 | B11: 2026.10.21 ~ 2026.11.02 (가계획, 작업일 11일, 공정표 시트 참조)
A12: 결제 조건 | B12: 협의 (예: 착수 30%, 준공 후 70%)
A13: 유효 기간 | B13: 견적일로부터 30일
A15: 아래와 같이 견적함.
A16: 합계 금액 (부가세 포함) | C16: 일금 칠천육백삼십사만육천육백원정 | G16: =원가계산서!E18 -> 76346600
A18: No | B18: 공 종 | D18: 작업 내용 | G18: 단위 | H18: 공급가액 | I18: 비고
A19: 1 | B19: 도비 작업 | D19: 회전·베이스 안착(100t·60t), 밀착 이동, 안전펜스 | G19: 식 | H19: =도비!$G$33 -> 26114000 | I19: 도비 시트 참조
A20: 2 | B20: 용접 작업 | D20: 접합면 사상, CO2 용접, 화재감시 | G20: 식 | H20: =용접!$G$29 -> 23795000 | I20: 용접 시트 참조
A21: 3 | B21: 베이스 작업 | D21: 임시 사다리형 베이스 제작·설치·회수 | G21: 식 | H21: =베이스!$G$34 -> 19497000 | I21: 베이스 시트 참조
A22: 공 급 가 액 | H22: =SUM(H19:H21) -> 69406000
A23: 부 가 세 (10%) | H23: =H22*0.1 -> 6940600
A24: 합 계 | H24: =H22+H23 -> 76346600
A26: 특기사항
A27: 1. 전기 수전, 배관·닥트 해체·복구, 보온, 도장, 시운전은 포함하지 않음.
A28: 2. 크레인 사양·배치는 인양계획서와 지반 검토 후 확정하며, 변경 시 정산함.
A29: 3. 베이스 H빔은 중고품 회수조건임. 발주처가 베이스를 소유하는 경우 2,584,083원(중고 구매가 기준)이 추가됨.
A30: 4. 비파괴검사(PT/UT)는 포함하지 않으며, 발주처 요구 시 별도 정산함.
A31: 5. 1일 8시간 기준이며, 연장·야간·휴일 작업과 발주처 사유 대기는 별도 협의함.
A32: 6. 작업구역(약 10×15m)은 이동식 안전펜스로 통제하며, 발주처 안전관리 규정과 출입 절차를 따름.
A33: 7. 대안(B안: 기존 조방 개조 + 전체 90° 회전)의 금액은 AB비교 시트에 정리함.
A35: 노란 칸은 공급자 정보·협의 항목으로 채워야 하는 칸임.

Sheet 원가계산서
A1: 공 사 원 가 계 산 서
A3: 공사명 : 진공건조로 회전·안착 및 접합부 용접 공사 | NMS-2610-KKT-01
A5: 비목 | B5: 도비 | C5: 용접 | D5: 베이스 | E5: 합계 | F5: 구성비
A6: 재료비 | B6: =도비!$G$23 -> 1380000 | C6: =용접!$G$19 -> 3680000 | D6: =베이스!$G$24 -> 9233700 | E6: =SUM(B6:D6) -> 14293700 | F6: =E6/$E$16 -> 0.20594329
A7: 노무비 | B7: =도비!$G$24 -> 8180000 | C7: =용접!$G$20 -> 9280000 | D7: =베이스!$G$25 -> 4680000 | E7: =SUM(B7:D7) -> 22140000 | F7: =E7/$E$16 -> 0.31899259
A8: 경비 | B8: =도비!$G$25 -> 12104400 | C8: =용접!$G$21 -> 6810000 | D8: =베이스!$G$26 -> 2955000 | E8: =SUM(B8:D8) -> 21869400 | F8: =E8/$E$16 -> 0.3150938
A9: 산재보험료 | B9: =도비!$G$26 -> 291208 | C9: =용접!$G$22 -> 330368 | D9: =베이스!$G$27 -> 166608 | E9: =SUM(B9:D9) -> 788184 | F9: =E9/$E$16 -> 0.011356136
A10: 고용보험료 | B10: =도비!$G$27 -> 94070 | C10: =용접!$G$23 -> 106720 | D10: =베이스!$G$28 -> 53820 | E10: =SUM(B10:D10) -> 254610 | F10: =E10/$E$16 -> 0.0036684148
A11: 산업안전보건관리비 | B11: =도비!$G$28 -> 297316 | C11: =용접!$G$24 -> 403056 | D11: =베이스!$G$29 -> 432716.07 | E11: =SUM(B11:D11) -> 1133088.1 | F11: =E11/$E$16 -> 0.016325506
A12: 순공사원가 | B12: =도비!$G$29 -> 22346994 | C12: =용접!$G$25 -> 20610144 | D12: =베이스!$G$30 -> 17521844 | E12: =SUM(B12:D12) -> 60478982 | F12: =E12/$E$16 -> 0.87137974
A13: 일반관리비 | B13: =도비!$G$30 -> 1117349.7 | C13: =용접!$G$26 -> 1030507.2 | D13: =베이스!$G$31 -> 876092.2 | E13: =SUM(B13:D13) -> 3023949.1 | F13: =E13/$E$16 -> 0.043568987
A14: 이윤 | B14: =도비!$G$31 -> 2650121.2 | C14: =용접!$G$27 -> 2155278.1 | D14: =베이스!$G$32 -> 1099708.4 | E14: =SUM(B14:D14) -> 5905107.7 | F14: =E14/$E$16 -> 0.085080652
A15: 단수정리 | B15: =도비!$G$32 -> -464.944 | C15: =용접!$G$28 -> -929.344 | D15: =베이스!$G$33 -> -644.62632 | E15: =SUM(B15:D15) -> -2038.9143 | F15: =E15/$E$16 -> -2.9376629e-05
A16: 공급가액 | B16: =도비!$G$33 -> 26114000 | C16: =용접!$G$29 -> 23795000 | D16: =베이스!$G$34 -> 19497000 | E16: =SUM(B16:D16) -> 69406000 | F16: =E16/$E$16 -> 1
A17: 부가가치세 (10%) | E17: =E16*0.1 -> 6940600
A18: 총 공사금액 | E18: =E16+E17 -> 76346600
A20: 요율: 산재 3.56%·고용 1.15% (노무비 기준), 산업안전보건관리비 3.11% ((재료비 + 노무비) 기준), 일반관리비 5% (순공사원가 기준), 이윤은 공종별 15% 이내. 근거는 '요율근거' 시트.

Sheet AB비교
A1: A안 · B안 금액 비교 (공급가액, 부가세 별도)
A3: 구분 | B3: A안 (임시 베이스 + 밀착 이동) | C3: B안 (조방 개조 + 90° 회전) | D3: 차액 (B − A) | E3: 비고
A4: 도비 | B4: =도비!$G$33 -> 26114000 | C4: =B_도비!$G$37 -> 36259000 | D4: =C4-B4 -> 10145000 | E4: B안: 200t급 크레인 1대 추가(전체 90° 회전) + 100t 테일링
A5: 용접 | B5: =용접!$G$29 -> 23795000 | C5: =B_용접!$G$29 -> 23795000 | D5: =C5-B5 -> 0 | E5: 같은 인원·장비로 상부·측면 용접 후 회전해서 하부 용접
A6: 베이스 / 조방 | B6: =베이스!$G$34 -> 19497000 | C6: =B_조방!$G$32 -> 8688000 | D6: =C6-B6 -> -10809000 | E6: B안: 신규 베이스(약 1,800만) 대신 조방 개조(약 800만), 배관 제거·복구 포함
A7: 공급가액 계 | B7: =SUM(B4:B6) -> 69406000 | C7: =SUM(C4:C6) -> 68742000 | D7: =SUM(D4:D6) -> -664000
A9: ※ B안 200t 크레인 단가는 업체 견적이 없어 사용자 제시 100t·60t 일대에서 톤급 비례로 외삽한 추정값임. 회송·웨이트 운반은 별도 줄로 넣음.
A10: ※ B안 회전은 일체 약 83t(45t + 38t)을 모서리 기준으로 세우는 작업으로, 실제 크레인 사양은 인양계획서·구조검토로 확정 필요함.
A11: ※ 회전 후 원래 자세로 되돌리는 회전이나 영구 받침이 필요하면 별도임.

Sheet 산출근거
A1: 견적 산출근거
A2: 금액은 공종 시트에서 연동됨(초록). 노란 칸은 업체 견적으로 확인할 가정값임.
A4: 공종 | B4: 품명 | C4: 규격 | D4: 산출식 | E4: 금액(원) | F4: 근거 | G4: 시중노임 참고
A5: 도비 | B5: 도비 전문기공 | C5: 회전·안착·밀착 이동 | D5: 7명 × 3일 × 300,000원 | E5: =도비!G8 -> 6300000 | F5: 인원 가정, 일수 사용자 제시, 단가 서해테크 도비 견적서(2026-10-10) 단가 | G5: 비계공 281,939원
A6: 도비 | B6: 신호수 | C6: 크레인 인양 신호 | D6: 2명 × 1일 × 260,000원 | E6: =도비!G9 -> 520000 | F6: 가정값 (업체 견적으로 확인 필요) | G6: 특별인부 226,122원
A7: 도비 | B7: 안전담당 (관리감독자) | C7: 작업 전 TBM·인양구역 통제 | D7: 1명 × 3일 × 320,000원 | E7: =도비!G10 -> 960000 | F7: 가정값 (업체 견적으로 확인 필요)
A8: 도비 | B8: 크레인 | C8: 100TON | D8: 1대 × 1일 × 2,400,000원 | E8: =도비!G11 -> 2400000 | F8: 사용자 제시
A9: 도비 | B9: 크레인 | C9: 60TON | D9: 1대 × 1일 × 1,700,000원 | E9: =도비!G12 -> 1700000 | F9: 사용자 제시
A10: 도비 | B10: 아웃리거 받침 철판 | C10: 1,500×1,500×25t, 8매 | D10: 8매 × 80,000원 | E10: =도비!G13 -> 640000 | F10: 가정값 (업체 견적으로 확인 필요)
A11: 도비 | B11: 밀착 이동 장비 | C11: 유압잭·윈치·스키드 | D11: 1식 (2일) | E11: =도비!G14 -> 2000000 | F11: 가정값 (업체 견적으로 확인 필요)
A12: 도비 | B12: 공구사용손료 | C12: 도비 전문장비·줄걸이구 | D12: 1식 | E12: =도비!G15 -> 3000000 | F12: 서해테크 도비 견적서(2026-10-10) 단가
A13: 도비 | B13: 소모품·잡자재 | C13: 목재 받침·와이어 보호대 등 | D13: 1식 | E13: =도비!G16 -> 1000000 | F13: 서해테크 도비 견적서(2026-10-10) 단가
A14: 도비 | B14: 안전펜스 임대 | C14: 이동식 메쉬펜스 H1.8×W2.4m | D14: 작업구역 10×15m, 둘레 50m ÷ 2.4m = 21매 + 출입문 1매 → 22매 × 11일 × 3,200원 | E14: =도비!G17 -> 774400 | F14: 가정값 (업체 견적으로 확인 필요)
A15: 도비 | B15: 펜스 설치·해체 | C15: 조공 | D15: 2명 × 1일 × 200,000원 | E15: =도비!G18 -> 400000 | F15: 가정값 (업체 견적으로 확인 필요) | G15: 보통인부 172,068원
A16: 도비 | B16: 펜스 운반 | C16: 1톤 화물 왕복 | D16: 2회 × 260,000원 | E16: =도비!G19 -> 520000 | F16: 가정값 (업체 견적으로 확인 필요)
A17: 도비 | B17: 출입통제·표지 | C17: 경광등·라바콘·표지판·차단봉 | D17: 1식 | E17: =도비!G20 -> 380000 | F17: 가정값 (업체 견적으로 확인 필요)
A18: 도비 | B18: 식대 | C18: 중식·간식·음료 | D18: 28인·일 × 20,000원 (중식 12,000 + 간식·음료 8,000) | E18: =도비!G21 -> 560000 | F18: 가정값 (업체 견적으로 확인 필요)
A19: 도비 | B19: 출장 교통비 | C19: 작업차량 유류·통행료 | D19: 2대 × 3일 × 85,000원 | E19: =도비!G22 -> 510000 | F19: 가정값 (업체 견적으로 확인 필요)
B20: 법정경비·일반관리비·이윤 | E20: =도비!$G$33-SUM(도비!$G$23:$G$25) -> 4449600 | F20: 요율근거 시트
B21: 공종 합계 | E21: =도비!$G$33 -> 26114000 | F21: 목표 약 20,000,000원 (사용자 제시)
A23: 용접 | B23: 용접사 | C23: CO2 용접 (접합부) | D23: 3명 × 3일 × 450,000원 | E23: =용접!G8 -> 4050000 | F23: 인원·일수 사용자 제시, 단가 현장 실거래 수준 적용 (사용자 지시: 용접사 상향, 고급기술자=제관사 수준) | G23: 플랜트용접공 292,640원
A24: 용접 | B24: 고급기술자 | C24: 제관사 수준 (취부·치수 관리) | D24: 2명 × 3일 × 330,000원 | E24: =용접!G9 -> 1980000 | F24: 인원·일수 사용자 제시, 단가 현장 실거래 수준 적용 (사용자 지시: 용접사 상향, 고급기술자=제관사 수준) | G24: 플랜트제관공 266,029원
A25: 용접 | B25: 사상 기술자 | C25: 접합면 그라인딩 | D25: 2명 × 2일 × 300,000원 | E25: =용접!G10 -> 1200000 | F25: 인원·일수 사용자 제시 | G25: 특별인부 226,122원
A26: 용접 | B26: 조공 | C26: 사상·용접 보조 | D26: 2명 × 2일 × 200,000원 | E26: =용접!G11 -> 800000 | F26: 인원·일수 사용자 제시 | G26: 보통인부 172,068원
A27: 용접 | B27: 화재감시자 | C27: 용접·사상 화기작업 전담 | D27: 1명 × 5일 × 250,000원 | E27: =용접!G12 -> 1250000 | F27: 산업안전보건기준에 관한 규칙 제241조의2, 단가 가정값 (업체 견적으로 확인 필요) | G27: 특별인부 226,122원
A28: 용접 | B28: CO2 용접기 대여 | C28: 500A급 | D28: 3대 × 3일 × 400,000원 | E28: =용접!G13 -> 3600000 | F28: 사용자 제시
A29: 용접 | B29: 그라인더·환기·조명 | C29: 송풍기, 투광등 포함 | D29: 1식 | E29: =용접!G14 -> 800000 | F29: 가정값 (업체 견적으로 확인 필요)
A30: 용접 | B30: 용접 소모품 | C30: CO2 가스·와이어·디스크·케이블·잡자재 | D30: 1식 (용접재 3,000,000 + 전원 케이블·잡자재 680,000) | E30: =용접!G15 -> 3680000 | F30: 가정값 (업체 견적으로 확인 필요), 사용자 지시로 분전반 항목 통합
A31: 용접 | B31: 작업발판 장비 대여 | C31: 우마·사다리·PT·아시바 | D31: 1식 (사용자 제시 약 100만원) | E31: =용접!G16 -> 1000000 | F31: 사용자 제시
A32: 용접 | B32: 식대 | C32: 중식·간식·음료 | D32: 28인·일 × 20,000원 (중식 12,000 + 간식·음료 8,000) | E32: =용접!G17 -> 560000 | F32: 가정값 (업체 견적으로 확인 필요)
A33: 용접 | B33: 출장 교통비 | C33: 작업차량 유류·통행료 | D33: 2대 × 5일 × 85,000원 | E33: =용접!G18 -> 850000 | F33: 가정값 (업체 견적으로 확인 필요)
B34: 법정경비·일반관리비·이윤 | E34: =용접!$G$29-SUM(용접!$G$19:$G$21) -> 4025000 | F34: 요율근거 시트
B35: 공종 합계 | E35: =용접!$G$29 -> 23795000 | F35: 목표 약 25,000,000원 (사용자 제시)
A37: 베이스 | B37: H빔 (회수조건) | C37: H-250×250×9×14, 10m 4·5m 16·0.6m 30EA | D37: 9,991kg × 700원 (중고 구매 9,577,783원 − 회수 고철가치 약 400만원 + 회수 손료) | E37: =베이스!G8 -> 6993700 | F37: 공급처 H빔 견적 + 사용자 제시 (회수조건 약 700만원)
A38: 베이스 | B38: H빔 반입 운임 | D38: 1식 | E38: =베이스!G9 -> 160000 | F38: 공급처 H빔 견적
A39: 베이스 | B39: 회수 반출 운임 | D39: 1식 | E39: =베이스!G10 -> 160000 | F39: 가정값 (업체 견적으로 확인 필요)
A40: 베이스 | B40: 용접 소모품 | C40: 용접봉·가스·디스크 | D40: 1식 | E40: =베이스!G11 -> 1000000 | F40: 가정값 (업체 견적으로 확인 필요)
A41: 베이스 | B41: 슬라이딩면 처리 | C41: 그리스·PTFE 시트 | D41: 1식 | E41: =베이스!G12 -> 500000 | F41: 가정값 (업체 견적으로 확인 필요)
A42: 베이스 | B42: 레벨 조정재 | C42: 라이너·심 플레이트 | D42: 1식 | E42: =베이스!G13 -> 420000 | F42: 가정값 (업체 견적으로 확인 필요)
A43: 베이스 | B43: 제관사 | C43: 절단·취부 | D43: 2명 × 3일 × 330,000원 | E43: =베이스!G14 -> 1980000 | F43: 인원 사용자 제시(4명), 직종 구성 가정 | G43: 플랜트제관공 266,029원
...

Sheet 도비
A1: 공 종 별 내 역 서
A3: 견적번호 NMS-2610-KKT-01 | 견적일 2026-10-12 | 금강변압기 유한회사 귀중
A5: 공 종 : 진공건조로 2기 회전·베이스 안착(1일), 용접면 밀착 이동(2일), 작업구역 안전펜스
A7: 구분 | B7: 품명 | C7: 규격 | D7: 단위 | E7: 수량 | F7: 단가 | G7: 금액 | H7: 비고 | I7: 비목
A8: 노무비 | B8: 도비 전문기공 | C8: 회전·안착·밀착 이동 | D8: 인·일 | E8: 21 | F8: 300000 | G8: =E8*F8 -> 6300000 | H8: 7명 × 3일 (안착 1 + 밀착 이동 2) | I8: 노무비
B9: 신호수 | C9: 크레인 인양 신호 | D9: 인·일 | E9: 2 | F9: 260000 | G9: =E9*F9 -> 520000 | H9: 2명 × 1일 (안착일) | I9: 노무비
B10: 안전담당 (관리감독자) | C10: 작업 전 TBM·인양구역 통제 | D10: 인·일 | E10: 3 | F10: 320000 | G10: =E10*F10 -> 960000 | H10: 1명 × 3일 | I10: 노무비
A11: 장비 | B11: 크레인 | C11: 100TON | D11: 대·일 | E11: 1 | F11: 2400000 | G11: =E11*F11 -> 2400000 | H11: 안착일 1일 | I11: 경비
B12: 크레인 | C12: 60TON | D12: 대·일 | E12: 1 | F12: 1700000 | G12: =E12*F12 -> 1700000 | H12: 안착일 1일 | I12: 경비
B13: 아웃리거 받침 철판 | C13: 1,500×1,500×25t, 8매 | D13: 식 | E13: 1 | F13: 640000 | G13: =E13*F13 -> 640000 | H13: 아스팔트 지반 보호 | I13: 경비
B14: 밀착 이동 장비 | C14: 유압잭·윈치·스키드 | D14: SET | E14: 1 | F14: 2000000 | G14: =E14*F14 -> 2000000 | H14: 밀착 이동 2일 | I14: 경비
B15: 공구사용손료 | C15: 도비 전문장비·줄걸이구 | D15: SET | E15: 1 | F15: 3000000 | G15: =E15*F15 -> 3000000 | I15: 경비
A16: 재료비 | B16: 소모품·잡자재 | C16: 목재 받침·와이어 보호대 등 | D16: 식 | E16: 1 | F16: 1000000 | G16: =E16*F16 -> 1000000 | I16: 재료비
A17: 안전시설 | B17: 안전펜스 임대 | C17: 이동식 메쉬펜스 H1.8×W2.4m | D17: 매·일 | E17: 242 | F17: 3200 | G17: =E17*F17 -> 774400 | H17: 22매(둘레 50m + 출입문) × 11일 | I17: 경비
B18: 펜스 설치·해체 | C18: 조공 | D18: 인·일 | E18: 2 | F18: 200000 | G18: =E18*F18 -> 400000 | H18: 설치 2명 × 0.5일 + 해체 2명 × 0.5일 | I18: 노무비
B19: 펜스 운반 | C19: 1톤 화물 왕복 | D19: 회 | E19: 2 | F19: 260000 | G19: =E19*F19 -> 520000 | H19: 반입 1 + 반출 1 | I19: 경비
B20: 출입통제·표지 | C20: 경광등·라바콘·표지판·차단봉 | D20: 식 | E20: 1 | F20: 380000 | G20: =E20*F20 -> 380000 | I20: 재료비
A21: 경비 | B21: 식대 | C21: 중식·간식·음료 | D21: 인·일 | E21: 28 | F21: 20000 | G21: =E21*F21 -> 560000 | H21: 도비 21 + 신호수 2 + 안전 3 + 펜스 2 | I21: 경비
B22: 출장 교통비 | C22: 작업차량 유류·통행료 | D22: 대·일 | E22: 6 | F22: 85000 | G22: =E22*F22 -> 510000 | H22: 2대 × 3일 | I22: 경비
A23: 재료비 계 | G23: =SUMIF($I$8:$I$22,"재료비",$G$8:$G$22) -> 1380000
A24: 노무비 계 | G24: =SUMIF($I$8:$I$22,"노무비",$G$8:$G$22) -> 8180000
A25: 경비 계 | G25: =SUMIF($I$8:$I$22,"경비",$G$8:$G$22) -> 12104400
A26: 산재보험료 | G26: =G24*요율근거!$C$5 -> 291208 | H26: 노무비 × 3.56%
A27: 고용보험료 | G27: =G24*요율근거!$C$6 -> 94070 | H27: 노무비 × 1.15%
A28: 산업안전보건관리비 | G28: =(G23+G24)*요율근거!$C$7 -> 297316 | H28: (재료비 + 노무비) × 3.11%
A29: 순공사원가 | G29: =SUM(G23:G28) -> 22346994
A30: 일반관리비 | G30: =G29*요율근거!$C$8 -> 1117349.7 | H30: 순공사원가 × 5%
A31: 이윤 | G31: =(G24+G25+G26+G27+G28+G30)*요율근거!$C$9 -> 2650121.2 | H31: (노무비 + 경비 + 일반관리비) × 12.0%
A32: 단수정리 | G32: =-MOD(G29+G30+G31,1000) -> -464.944 | H32: 천원 미만 절사
A33: 공종 합계 | G33: =G29+G30+G31+G32 -> 26114000 | H33: 부가세 별도
A35: ※ 파란 글씨는 수량·단가 입력값이며, 근거는 '산출근거'·'요율근거' 시트에 정리함.
A36: ※ 1일 8시간 기준임. 연장·야간 작업 시 별도 협의함.

Sheet 용접
A1: 공 종 별 내 역 서
A3: 견적번호 NMS-2610-KKT-01 | 견적일 2026-10-12 | 금강변압기 유한회사 귀중
A5: 공 종 : 접합면 사상(2일) 및 접합부 CO2 용접(3일)
A7: 구분 | B7: 품명 | C7: 규격 | D7: 단위 | E7: 수량 | F7: 단가 | G7: 금액 | H7: 비고 | I7: 비목
A8: 노무비 | B8: 용접사 | C8: CO2 용접 (접합부) | D8: 인·일 | E8: 9 | F8: 450000 | G8: =E8*F8 -> 4050000 | H8: 3명 × 3일 | I8: 노무비
B9: 고급기술자 | C9: 제관사 수준 (취부·치수 관리) | D9: 인·일 | E9: 6 | F9: 330000 | G9: =E9*F9 -> 1980000 | H9: 2명 × 3일 | I9: 노무비
B10: 사상 기술자 | C10: 접합면 그라인딩 | D10: 인·일 | E10: 4 | F10: 300000 | G10: =E10*F10 -> 1200000 | H10: 2명 × 2일 | I10: 노무비
B11: 조공 | C11: 사상·용접 보조 | D11: 인·일 | E11: 4 | F11: 200000 | G11: =E11*F11 -> 800000 | H11: 2명 × 2일 | I11: 노무비
B12: 화재감시자 | C12: 용접·사상 화기작업 전담 | D12: 인·일 | E12: 5 | F12: 250000 | G12: =E12*F12 -> 1250000 | H12: 1명 × 5일 (사상 2 + 용접 3) | I12: 노무비
A13: 장비 | B13: CO2 용접기 대여 | C13: 500A급 | D13: 대·일 | E13: 9 | F13: 400000 | G13: =E13*F13 -> 3600000 | H13: 3대 × 3일 | I13: 경비
B14: 그라인더·환기·조명 | C14: 송풍기, 투광등 포함 | D14: SET | E14: 1 | F14: 800000 | G14: =E14*F14 -> 800000 | I14: 경비
A15: 재료비 | B15: 용접 소모품 | C15: CO2 가스·와이어·디스크·케이블·잡자재 | D15: 식 | E15: 1 | F15: 3680000 | G15: =E15*F15 -> 3680000 | H15: 임시 분전반 비용 포함 | I15: 재료비
A16: 장비 | B16: 작업발판 장비 대여 | C16: 우마·사다리·PT·아시바 | D16: 식 | E16: 1 | F16: 1000000 | G16: =E16*F16 -> 1000000 | H16: 상부·측면·하부 접근 | I16: 경비
A17: 경비 | B17: 식대 | C17: 중식·간식·음료 | D17: 인·일 | E17: 28 | F17: 20000 | G17: =E17*F17 -> 560000 | H17: 용접 15 + 사상 8 + 화재감시 5 | I17: 경비
B18: 출장 교통비 | C18: 작업차량 유류·통행료 | D18: 대·일 | E18: 10 | F18: 85000 | G18: =E18*F18 -> 850000 | H18: 2대 × 5일 | I18: 경비
A19: 재료비 계 | G19: =SUMIF($I$8:$I$18,"재료비",$G$8:$G$18) -> 3680000
A20: 노무비 계 | G20: =SUMIF($I$8:$I$18,"노무비",$G$8:$G$18) -> 9280000
A21: 경비 계 | G21: =SUMIF($I$8:$I$18,"경비",$G$8:$G$18) -> 6810000
A22: 산재보험료 | G22: =G20*요율근거!$C$5 -> 330368 | H22: 노무비 × 3.56%
A23: 고용보험료 | G23: =G20*요율근거!$C$6 -> 106720 | H23: 노무비 × 1.15%
A24: 산업안전보건관리비 | G24: =(G19+G20)*요율근거!$C$7 -> 403056 | H24: (재료비 + 노무비) × 3.11%
A25: 순공사원가 | G25: =SUM(G19:G24) -> 20610144
A26: 일반관리비 | G26: =G25*요율근거!$C$8 -> 1030507.2 | H26: 순공사원가 × 5%
A27: 이윤 | G27: =(G20+G21+G22+G23+G24+G26)*요율근거!$C$10 -> 2155278.1 | H27: (노무비 + 경비 + 일반관리비) × 12.0%
A28: 단수정리 | G28: =-MOD(G25+G26+G27,1000) -> -929.344 | H28: 천원 미만 절사
A29: 공종 합계 | G29: =G25+G26+G27+G28 -> 23795000 | H29: 부가세 별도
A31: ※ 파란 글씨는 수량·단가 입력값이며, 근거는 '산출근거'·'요율근거' 시트에 정리함.
A32: ※ 1일 8시간 기준임. 연장·야간 작업 시 별도 협의함.

Sheet 베이스
A1: 공 종 별 내 역 서
A3: 견적번호 NMS-2610-KKT-01 | 견적일 2026-10-12 | 금강변압기 유한회사 귀중
A5: 공 종 : 사다리형 일체 임시 베이스 제작·설치 및 공사 후 회수, H-250×250
A7: 구분 | B7: 품명 | C7: 규격 | D7: 단위 | E7: 수량 | F7: 단가 | G7: 금액 | H7: 비고 | I7: 비목
A8: 재료비 | B8: H빔 (회수조건) | C8: H-250×250×9×14, 10m 4·5m 16·0.6m 30EA | D8: kg | E8: 9991 | F8: 700 | G8: =E8*F8 -> 6993700 | H8: 공사 후 회수, 중고 구매가 9,577,783원 | I8: 재료비
B9: H빔 반입 운임 | D9: 식 | E9: 1 | F9: 160000 | G9: =E9*F9 -> 160000 | I9: 재료비
B10: 회수 반출 운임 | D10: 식 | E10: 1 | F10: 160000 | G10: =E10*F10 -> 160000 | H10: 반입 운임과 같게 적용 | I10: 재료비
B11: 용접 소모품 | C11: 용접봉·가스·디스크 | D11: 식 | E11: 1 | F11: 1000000 | G11: =E11*F11 -> 1000000 | I11: 재료비
B12: 슬라이딩면 처리 | C12: 그리스·PTFE 시트 | D12: 식 | E12: 1 | F12: 500000 | G12: =E12*F12 -> 500000 | H12: 밀착 이동용 레일 상면 | I12: 재료비
B13: 레벨 조정재 | C13: 라이너·심 플레이트 | D13: 식 | E13: 1 | F13: 420000 | G13: =E13*F13 -> 420000 | H13: 베이스 수평 ±2mm | I13: 재료비
A14: 노무비 | B14: 제관사 | C14: 절단·취부 | D14: 인·일 | E14: 6 | F14: 330000 | G14: =E14*F14 -> 1980000 | H14: 2명 × 3일 | I14: 노무비
B15: 용접사 | C15: 베이스 조립 용접 | D15: 인·일 | E15: 3 | F15: 450000 | G15: =E15*F15 -> 1350000 | H15: 1명 × 3일 | I15: 노무비
B16: 조공 | C16: 자재 정리·보조 | D16: 인·일 | E16: 3 | F16: 200000 | G16: =E16*F16 -> 600000 | H16: 1명 × 3일 | I16: 노무비
B17: 화재감시자 | C17: 용접·절단 화기작업 전담 | D17: 인·일 | E17: 3 | F17: 250000 | G17: =E17*F17 -> 750000 | H17: 1명 × 3일 | I17: 노무비
A18: 장비 | B18: 지게차 | C18: 자재 하역·조립 | D18: 일 | E18: 2 | F18: 300000 | G18: =E18*F18 -> 600000 | I18: 경비
B19: 지게차 | C19: 회수 시 해체·상차 | D19: 일 | E19: 1 | F19: 300000 | G19: =E19*F19 -> 300000 | I19: 경비
B20: CO2 용접기 대여 | C20: 500A급 | D20: 대·일 | E20: 3 | F20: 400000 | G20: =E20*F20 -> 1200000 | H20: 1대 × 3일 | I20: 경비
B21: 절단기 | C21: 산소·LPG 가스절단기 | D21: 식 | E21: 1 | F21: 300000 | G21: =E21*F21 -> 300000 | I21: 경비
A22: 경비 | B22: 식대 | C22: 중식·간식·음료 | D22: 인·일 | E22: 15 | F22: 20000 | G22: =E22*F22 -> 300000 | H22: 제작 12 + 화재감시 3 | I22: 경비
B23: 출장 교통비 | C23: 작업차량 유류·통행료 | D23: 대·일 | E23: 3 | F23: 85000 | G23: =E23*F23 -> 255000 | H23: 1대 × 3일 | I23: 경비
A24: 재료비 계 | G24: =SUMIF($I$8:$I$23,"재료비",$G$8:$G$23) -> 9233700
A25: 노무비 계 | G25: =SUMIF($I$8:$I$23,"노무비",$G$8:$G$23) -> 4680000
A26: 경비 계 | G26: =SUMIF($I$8:$I$23,"경비",$G$8:$G$23) -> 2955000
A27: 산재보험료 | G27: =G25*요율근거!$C$5 -> 166608 | H27: 노무비 × 3.56%
A28: 고용보험료 | G28: =G25*요율근거!$C$6 -> 53820 | H28: 노무비 × 1.15%
A29: 산업안전보건관리비 | G29: =(G24+G25)*요율근거!$C$7 -> 432716.07 | H29: (재료비 + 노무비) × 3.11%
A30: 순공사원가 | G30: =SUM(G24:G29) -> 17521844
A31: 일반관리비 | G31: =G30*요율근거!$C$8 -> 876092.2 | H31: 순공사원가 × 5%
A32: 이윤 | G32: =(G25+G26+G27+G28+G29+G31)*요율근거!$C$11 -> 1099708.4 | H32: (노무비 + 경비 + 일반관리비) × 12.0%
A33: 단수정리 | G33: =-MOD(G30+G31+G32,1000) -> -644.62632 | H33: 천원 미만 절사
A34: 공종 합계 | G34: =G30+G31+G32+G33 -> 19497000 | H34: 부가세 별도
A36: ※ 파란 글씨는 수량·단가 입력값이며, 근거는 '산출근거'·'요율근거' 시트에 정리함.
A37: ※ 1일 8시간 기준임. 연장·야간 작업 시 별도 협의함.

Sheet B_도비
A1: 공 종 별 내 역 서
A3: 견적번호 NMS-2610-KKT-01 | 견적일 2026-10-12 | 금강변압기 유한회사 귀중
A5: 공 종 : B안: 조방 안착(100t·60t) + 전체 90° 회전(200t 주 + 100t 테일링), 안전펜스
A7: 구분 | B7: 품명 | C7: 규격 | D7: 단위 | E7: 수량 | F7: 단가 | G7: 금액 | H7: 비고 | I7: 비목
A8: 노무비 | B8: 도비 전문기공 | C8: 안착·회전 준비·90° 회전 | D8: 인·일 | E8: 21 | F8: 300000 | G8: =E8*F8 -> 6300000 | H8: 7명 × 3일 (안착 1 + 회전 준비 1 + 회전 1) | I8: 노무비
B9: 신호수 | C9: 크레인 인양 신호 | D9: 인·일 | E9: 4 | F9: 260000 | G9: =E9*F9 -> 1040000 | H9: 2명 × 2일 (안착일 + 회전일) | I9: 노무비
B10: 안전담당 (관리감독자) | C10: 인양구역 통제 | D10: 인·일 | E10: 3 | F10: 320000 | G10: =E10*F10 -> 960000 | H10: 1명 × 3일 | I10: 노무비
A11: 장비 | B11: 크레인 | C11: 100TON (안착) | D11: 대·일 | E11: 1 | F11: 2400000 | G11: =E11*F11 -> 2400000 | H11: 안착일 | I11: 경비
B12: 크레인 | C12: 60TON (안착) | D12: 대·일 | E12: 1 | F12: 1700000 | G12: =E12*F12 -> 1700000 | H12: 안착일 | I12: 경비
B13: 크레인 | C13: 200TON (90° 회전 주 크레인) | D13: 대·일 | E13: 1 | F13: 4150000 | G13: =E13*F13 -> 4150000 | H13: 회전일, 일체 약 83t | I13: 경비
B14: 200TON 회송·웨이트 운반 | C14: 카운터웨이트 트레일러 왕복 | D14: 식 | E14: 1 | F14: 1200000 | G14: =E14*F14 -> 1200000 | H14: 대형 크레인 부대비 | I14: 경비
B15: 크레인 | C15: 100TON (회전 테일링) | D15: 대·일 | E15: 1 | F15: 2400000 | G15: =E15*F15 -> 2400000 | H15: 회전 시 하단 잡아주기 | I15: 경비
B16: 회전용 대형 줄걸이 | C16: 100t급 샤클·슬링·스프레더 손료 | D16: 식 | E16: 1 | F16: 800000 | G16: =E16*F16 -> 800000 | I16: 경비
B17: 아웃리거 받침 철판 | C17: 1,500×1,500×25t, 8매 | D17: 회 | E17: 2 | F17: 640000 | G17: =E17*F17 -> 1280000 | H17: 안착일 + 회전일 | I17: 경비
B18: 공구사용손료 | C18: 도비 전문장비·줄걸이구 | D18: SET | E18: 1 | F18: 3000000 | G18: =E18*F18 -> 3000000 | I18: 경비
A19: 재료비 | B19: 회전 착지 깔목·고무판 | C19: 목재 받침 300×300, 고무판 | D19: 식 | E19: 1 | F19: 900000 | G19: =E19*F19 -> 900000 | H19: 회전 후 착지면 보호 | I19: 재료비
B20: 소모품·잡자재 | C20: 와이어 보호대 등 | D20: 식 | E20: 1 | F20: 1000000 | G20: =E20*F20 -> 1000000 | I20: 재료비
A21: 안전시설 | B21: 안전펜스 임대 | C21: 이동식 메쉬펜스 H1.8×W2.4m | D21: 매·일 | E21: 242 | F21: 3200 | G21: =E21*F21 -> 774400 | H21: 22매 × 11일 | I21: 경비
B22: 펜스 설치·해체 | C22: 조공 | D22: 인·일 | E22: 2 | F22: 200000 | G22: =E22*F22 -> 400000 | I22: 노무비
B23: 펜스 운반 | C23: 1톤 화물 왕복 | D23: 회 | E23: 2 | F23: 260000 | G23: =E23*F23 -> 520000 | I23: 경비
B24: 출입통제·표지 | C24: 경광등·라바콘·표지판·차단봉 | D24: 식 | E24: 1 | F24: 380000 | G24: =E24*F24 -> 380000 | I24: 재료비
A25: 경비 | B25: 식대 | C25: 중식·간식·음료 | D25: 인·일 | E25: 30 | F25: 20000 | G25: =E25*F25 -> 600000 | H25: 도비 21 + 신호수 4 + 안전 3 + 펜스 2 | I25: 경비
B26: 출장 교통비 | C26: 작업차량 유류·통행료 | D26: 대·일 | E26: 6 | F26: 85000 | G26: =E26*F26 -> 510000 | H26: 2대 × 3일 | I26: 경비
A27: 재료비 계 | G27: =SUMIF($I$8:$I$26,"재료비",$G$8:$G$26) -> 2280000
A28: 노무비 계 | G28: =SUMIF($I$8:$I$26,"노무비",$G$8:$G$26) -> 8700000
A29: 경비 계 | G29: =SUMIF($I$8:$I$26,"경비",$G$8:$G$26) -> 19334400
A30: 산재보험료 | G30: =G28*요율근거!$C$5 -> 309720 | H30: 노무비 × 3.56%
A31: 고용보험료 | G31: =G28*요율근거!$C$6 -> 100050 | H31: 노무비 × 1.15%
A32: 산업안전보건관리비 | G32: =(G27+G28)*요율근거!$C$7 -> 341478 | H32: (재료비 + 노무비) × 3.11%
A33: 순공사원가 | G33: =SUM(G27:G32) -> 31065648
A34: 일반관리비 | G34: =G33*요율근거!$C$8 -> 1553282.4 | H34: 순공사원가 × 5%
A35: 이윤 | G35: =(G28+G29+G30+G31+G32+G34)*요율근거!$C$12 -> 3640671.6 | H35: (노무비 + 경비 + 일반관리비) × 12.0%
A36: 단수정리 | G36: =-MOD(G33+G34+G35,1000) -> -602.048 | H36: 천원 미만 절사
A37: 공종 합계 | G37: =G33+G34+G35+G36 -> 36259000 | H37: 부가세 별도
A39: ※ 파란 글씨는 수량·단가 입력값이며, 근거는 '산출근거'·'요율근거' 시트에 정리함.
A40: ※ 1일 8시간 기준임. 연장·야간 작업 시 별도 협의함.

Sheet B_용접
A1: 공 종 별 내 역 서
A3: 견적번호 NMS-2610-KKT-01 | 견적일 2026-10-12 | 금강변압기 유한회사 귀중
A5: 공 종 : B안: 사상, 상부·측면 용접 → 회전 후 하부 용접
A7: 구분 | B7: 품명 | C7: 규격 | D7: 단위 | E7: 수량 | F7: 단가 | G7: 금액 | H7: 비고 | I7: 비목
A8: 노무비 | B8: 용접사 | C8: CO2 용접 (접합부) | D8: 인·일 | E8: 9 | F8: 450000 | G8: =E8*F8 -> 4050000 | H8: 3명 × 3일 | I8: 노무비
B9: 고급기술자 | C9: 제관사 수준 (취부·치수 관리) | D9: 인·일 | E9: 6 | F9: 330000 | G9: =E9*F9 -> 1980000 | H9: 2명 × 3일 | I9: 노무비
B10: 사상 기술자 | C10: 접합면 그라인딩 | D10: 인·일 | E10: 4 | F10: 300000 | G10: =E10*F10 -> 1200000 | H10: 2명 × 2일 | I10: 노무비
B11: 조공 | C11: 사상·용접 보조 | D11: 인·일 | E11: 4 | F11: 200000 | G11: =E11*F11 -> 800000 | H11: 2명 × 2일 | I11: 노무비
B12: 화재감시자 | C12: 용접·사상 화기작업 전담 | D12: 인·일 | E12: 5 | F12: 250000 | G12: =E12*F12 -> 1250000 | H12: 1명 × 5일 (사상 2 + 용접 3) | I12: 노무비
A13: 장비 | B13: CO2 용접기 대여 | C13: 500A급 | D13: 대·일 | E13: 9 | F13: 400000 | G13: =E13*F13 -> 3600000 | H13: 3대 × 3일 | I13: 경비
B14: 그라인더·환기·조명 | C14: 송풍기, 투광등 포함 | D14: SET | E14: 1 | F14: 800000 | G14: =E14*F14 -> 800000 | I14: 경비
A15: 재료비 | B15: 용접 소모품 | C15: CO2 가스·와이어·디스크·케이블·잡자재 | D15: 식 | E15: 1 | F15: 3680000 | G15: =E15*F15 -> 3680000 | H15: 임시 분전반 비용 포함 | I15: 재료비
A16: 장비 | B16: 작업발판 장비 대여 | C16: 우마·사다리·PT·아시바 | D16: 식 | E16: 1 | F16: 1000000 | G16: =E16*F16 -> 1000000 | H16: 상부·측면·하부 접근 | I16: 경비
A17: 경비 | B17: 식대 | C17: 중식·간식·음료 | D17: 인·일 | E17: 28 | F17: 20000 | G17: =E17*F17 -> 560000 | H17: 용접 15 + 사상 8 + 화재감시 5 | I17: 경비
B18: 출장 교통비 | C18: 작업차량 유류·통행료 | D18: 대·일 | E18: 10 | F18: 85000 | G18: =E18*F18 -> 850000 | H18: 2대 × 5일 | I18: 경비
A19: 재료비 계 | G19: =SUMIF($I$8:$I$18,"재료비",$G$8:$G$18) -> 3680000
A20: 노무비 계 | G20: =SUMIF($I$8:$I$18,"노무비",$G$8:$G$18) -> 9280000
A21: 경비 계 | G21: =SUMIF($I$8:$I$18,"경비",$G$8:$G$18) -> 6810000
A22: 산재보험료 | G22: =G20*요율근거!$C$5 -> 330368 | H22: 노무비 × 3.56%
A23: 고용보험료 | G23: =G20*요율근거!$C$6 -> 106720 | H23: 노무비 × 1.15%
A24: 산업안전보건관리비 | G24: =(G19+G20)*요율근거!$C$7 -> 403056 | H24: (재료비 + 노무비) × 3.11%
A25: 순공사원가 | G25: =SUM(G19:G24) -> 20610144
A26: 일반관리비 | G26: =G25*요율근거!$C$8 -> 1030507.2 | H26: 순공사원가 × 5%
A27: 이윤 | G27: =(G20+G21+G22+G23+G24+G26)*요율근거!$C$13 -> 2155278.1 | H27: (노무비 + 경비 + 일반관리비) × 12.0%
A28: 단수정리 | G28: =-MOD(G25+G26+G27,1000) -> -929.344 | H28: 천원 미만 절사
A29: 공종 합계 | G29: =G25+G26+G27+G28 -> 23795000 | H29: 부가세 별도
A31: ※ 파란 글씨는 수량·단가 입력값이며, 근거는 '산출근거'·'요율근거' 시트에 정리함.
A32: ※ 1일 8시간 기준임. 연장·야간 작업 시 별도 협의함.

Sheet B_조방
A1: 공 종 별 내 역 서
A3: 견적번호 NMS-2610-KKT-01 | 견적일 2026-10-12 | 금강변압기 유한회사 귀중
A5: 공 종 : B안: 기존 조방 7×3m 개조(보강보), 바닥 접촉면 배관 제거·복구
A7: 구분 | B7: 품명 | C7: 규격 | D7: 단위 | E7: 수량 | F7: 단가 | G7: 금액 | H7: 비고 | I7: 비목
A8: 재료비 | B8: 보강보 (회수조건) | C8: H-200×200×8×12, 약 25m | D8: kg | E8: 1248 | F8: 700 | G8: =E8*F8 -> 873600 | H8: 25m × 49.9kg/m, 공사 후 회수 | I8: 재료비
B9: 보강보 운임 | C9: 반입·반출 | D9: 회 | E9: 2 | F9: 160000 | G9: =E9*F9 -> 320000 | I9: 재료비
B10: 용접 소모품 | C10: 용접봉·가스·디스크 | D10: 식 | E10: 1 | F10: 420000 | G10: =E10*F10 -> 420000 | I10: 재료비
B11: 레벨 조정재 | C11: 라이너·심 플레이트 | D11: 식 | E11: 1 | F11: 230000 | G11: =E11*F11 -> 230000 | I11: 재료비
B12: 배관 복구 자재 | C12: 가스켓·볼트·너트 | D12: 식 | E12: 1 | F12: 380000 | G12: =E12*F12 -> 380000 | H12: 제거한 배관 재조립용 | I12: 재료비
A13: 노무비 | B13: 제관사 | C13: 조방 보강보 취부 | D13: 인·일 | E13: 2 | F13: 330000 | G13: =E13*F13 -> 660000 | H13: 2명 × 1일 | I13: 노무비
B14: 용접사 | C14: 보강보 용접 | D14: 인·일 | E14: 2 | F14: 450000 | G14: =E14*F14 -> 900000 | H14: 2명 × 1일 | I14: 노무비
B15: 조공 | C15: 보조 | D15: 인·일 | E15: 2 | F15: 200000 | G15: =E15*F15 -> 400000 | H15: 2명 × 1일 | I15: 노무비
B16: 화재감시자 | C16: 화기작업 전담 | D16: 인·일 | E16: 1 | F16: 250000 | G16: =E16*F16 -> 250000 | H16: 1명 × 1일 | I16: 노무비
B17: 배관공 | C17: 바닥 접촉면 배관 제거·복구 | D17: 인·일 | E17: 4 | F17: 350000 | G17: =E17*F17 -> 1400000 | H17: 2명 × 2일 (제거 1 + 복구 1) | I17: 노무비
A18: 장비 | B18: CO2 용접기 대여 | C18: 500A급 | D18: 대·일 | E18: 2 | F18: 400000 | G18: =E18*F18 -> 800000 | H18: 2대 × 1일 | I18: 경비
B19: 절단기 | C19: 산소·LPG 가스절단기 | D19: 식 | E19: 1 | F19: 240000 | G19: =E19*F19 -> 240000 | I19: 경비
A20: 경비 | B20: 식대 | C20: 중식·간식·음료 | D20: 인·일 | E20: 11 | F20: 20000 | G20: =E20*F20 -> 220000 | H20: 조방 개조 7 + 배관 4 | I20: 경비
B21: 출장 교통비 | C21: 작업차량 유류·통행료 | D21: 대·일 | E21: 2 | F21: 85000 | G21: =E21*F21 -> 170000 | H21: 1대 × 2일 | I21: 경비
A22: 재료비 계 | G22: =SUMIF($I$8:$I$21,"재료비",$G$8:$G$21) -> 2223600
A23: 노무비 계 | G23: =SUMIF($I$8:$I$21,"노무비",$G$8:$G$21) -> 3610000
A24: 경비 계 | G24: =SUMIF($I$8:$I$21,"경비",$G$8:$G$21) -> 1430000
A25: 산재보험료 | G25: =G23*요율근거!$C$5 -> 128516 | H25: 노무비 × 3.56%
A26: 고용보험료 | G26: =G23*요율근거!$C$6 -> 41515 | H26: 노무비 × 1.15%
A27: 산업안전보건관리비 | G27: =(G22+G23)*요율근거!$C$7 -> 181424.96 | H27: (재료비 + 노무비) × 3.11%
A28: 순공사원가 | G28: =SUM(G22:G27) -> 7615056
A29: 일반관리비 | G29: =G28*요율근거!$C$8 -> 380752.8 | H29: 순공사원가 × 5%
A30: 이윤 | G30: =(G23+G24+G25+G26+G27+G29)*요율근거!$C$14 -> 692665.05 | H30: (노무비 + 경비 + 일반관리비) × 12.0%
A31: 단수정리 | G31: =-MOD(G28+G29+G30,1000) -> -473.80896 | H31: 천원 미만 절사
A32: 공종 합계 | G32: =G28+G29+G30+G31 -> 8688000 | H32: 부가세 별도
A34: ※ 파란 글씨는 수량·단가 입력값이며, 근거는 '산출근거'·'요율근거' 시트에 정리함.
A35: ※ 1일 8시간 기준임. 연장·야간 작업 시 별도 협의함.

Sheet 베이스자재
A1: 베이스 자재: H-250×250×9×14 (공급처 견적, 부가세 미포함)
A3: 길이(m) | B3: 수량(EA) | C3: 총 길이(m) | D3: 단위중량(kg/m) | E3: 중량(kg)
A4: 10 | B4: 4 | C4: =A4*B4 -> 40 | D4: 72.4 | E4: =C4*D4 -> 2896
A5: 5 | B5: 16 | C5: =A5*B5 -> 80 | D5: 72.4 | E5: =C5*D5 -> 5792
A6: 0.6 | B6: 30 | C6: =A6*B6 -> 18 | D6: 72.4 | E6: =C6*D6 -> 1303.2
B7: 합계 | C7: =SUM(C4:C6) -> 138 | E7: =SUM(E4:E6) -> 9991.2
A9: 구분 | B9: 금액(원) | C9: kg당(원) | D9: 비고
A10: 신품 구매 | B10: 13575440 | C10: =B10/$E$7 -> 1358.7397 | D10: 공급처 견적
A11: 중고 구매 | B11: 9577783 | C11: =B11/$E$7 -> 958.62189 | D11: 공급처 견적
A12: 고철 매각 예상 | B12: 4000000 | C12: =B12/$E$7 -> 400.35231 | D12: 사용자 제시 (약 400만원)
A13: 회수조건 적용 | B13: =E7*700 -> 6993840 | C13: =B13/$E$7 -> 700 | D13: kg당 700원, 견적 반영
A14: 회수 손료 (차액) | B14: =B13-(B11-B12) -> 1416057 | C14: =B14/$E$7 -> 141.73042 | D14: 중고 구매가 − 고철가치 대비 추가분
A16: 단위중량 72.4 kg/m는 KS H-250×250×9×14 공칭값임. 베이스는 임시 구조물로 방청·도장 미적용.

Sheet 공정표
A1: 공정표 (가계획 2026.10.21 ~ 11.02, 작업일 11일)
A3: 공정 | B3: 투입 인원 | C3: 10/21 수 | D3: 10/22 목 | E3: 10/23 금 | F3: 10/24 토 | G3: 10/26 월 | H3: 10/27 화 | I3: 10/28 수 | J3: 10/29 목 | K3: 10/30 금 | L3: 10/31 토 | M3: 11/2 월
A4: 안전펜스 설치·작업구역 통제 | B4: 조공 2명
A5: 베이스 제작·설치 | B5: 제관 2, 용접 1, 조공 1, 화재감시 1
A6: 회전·베이스 안착 (100t + 60t) | B6: 도비 7명, 신호수 2, 안전담당
A7: 접합면 사상 | B7: 사상 2, 조공 2, 화재감시 1
A8: 용접면 밀착 이동 | B8: 도비 7명, 안전담당
A9: 접합부 용접 | B9: 용접사 3, 고급기술자 2, 화재감시 1
A10: 펜스 해체·정리 | B10: 조공 2명
A12: 가계획: 2026-10-21(수) 착공 ~ 11-02(월) 완료, 일요일 휴무 기준 작업일 11일. 착공일은 발주처 협의로 확정함.

Sheet 요율근거
A1: 요율 및 단가 근거
A2: 파란 글씨는 입력값임. 변경 시 모든 공종 시트와 견적서가 다시 계산됨.
A4: 항목 | B4: 적용 기준 | C4: 요율 | D4: 출처·비고
A5: 산재보험료 | B5: 노무비 × | C5: 0.0356 | D5: 고용노동부 2026년 보험료율 고시 (대한전문건설협회 안내자료): 건설업 3.56% (출퇴근재해 0.06% 포함)
A6: 고용보험료 | B6: 노무비 × | C6: 0.0115 | D6: 고용노동부 2026년 보험료율 고시 (대한전문건설협회 안내자료): 실업급여 사업주 0.9% + 고용안정·직업능력개발 0.25% (150인 미만)
A7: 산업안전보건관리비 | B7: (재료비 + 노무비) × | C7: 0.0311 | D7: 고용노동부 건설업 산업안전보건관리비 계상 및 사용기준 (5억 미만 건축공사 3.11%). 총공사금액 2천만원 이상 의무 계상
A8: 일반관리비 | B8: 순공사원가 × | C8: 0.05 | D8: 국가계약법 시행규칙 제8조 (일반관리비 6%·이윤 15% 상한, 민간공사 참고). 6% 이내에서 5% 적용
A9: 이윤 (도비) | B9: (노무비 + 경비 + 일반관리비) × | C9: 0.12 | D9: 국가계약법 시행규칙 제8조 (일반관리비 6%·이윤 15% 상한, 민간공사 참고). 15% 이내
A10: 이윤 (용접) | B10: (노무비 + 경비 + 일반관리비) × | C10: 0.12 | D10: 국가계약법 시행규칙 제8조 (일반관리비 6%·이윤 15% 상한, 민간공사 참고). 15% 이내
A11: 이윤 (베이스) | B11: (노무비 + 경비 + 일반관리비) × | C11: 0.12 | D11: 국가계약법 시행규칙 제8조 (일반관리비 6%·이윤 15% 상한, 민간공사 참고). 15% 이내
A12: 이윤 (B_도비) | B12: (노무비 + 경비 + 일반관리비) × | C12: 0.12 | D12: 국가계약법 시행규칙 제8조 (일반관리비 6%·이윤 15% 상한, 민간공사 참고). 15% 이내
A13: 이윤 (B_용접) | B13: (노무비 + 경비 + 일반관리비) × | C13: 0.12 | D13: 국가계약법 시행규칙 제8조 (일반관리비 6%·이윤 15% 상한, 민간공사 참고). 15% 이내
A14: 이윤 (B_조방) | B14: (노무비 + 경비 + 일반관리비) × | C14: 0.12 | D14: 국가계약법 시행규칙 제8조 (일반관리비 6%·이윤 15% 상한, 민간공사 참고). 15% 이내
A15: 국민연금·건강·장기요양 | B15: 미계상 | C15: - | D15: 1인 투입 3~5일로 건설일용 사업장가입 기준(월 8일 이상 또는 월 220만원 이상)에 미달하는 것으로 봄. 인원 운용이 바뀌면 국민연금 4.75%, 건강 3.545%, 장기요양(건강보험료의 12.95%) 추가
A17: 시중노임 대비 적용 단가
A18: 직종 (견적) | B18: 시중노임 직종 | C18: 시중노임(원/일) | D18: 적용 단가(원/일) | E18: 배율
A19: 용접사 | B19: 플랜트용접공 | C19: 292640 | D19: 450000 | E19: =D19/C19 -> 1.5377255
A20: 고급기술자·제관사 | B20: 플랜트제관공 | C20: 266029 | D20: 330000 | E20: =D20/C20 -> 1.2404663
A21: 사상 기술자 | B21: 특별인부 | C21: 226122 | D21: 300000 | E21: =D21/C21 -> 1.3267174
A22: 조공 | B22: 보통인부 | C22: 172068 | D22: 200000 | E22: =D22/C22 -> 1.1623312
A23: 화재감시자 | B23: 특별인부 | C23: 226122 | D23: 250000 | E23: =D23/C23 -> 1.1055979
A24: 신호수 | B24: 특별인부 | C24: 226122 | D24: 260000 | E24: =D24/C24 -> 1.1498218
A25: 도비 전문기공 | B25: 비계공 | C25: 281939 | D25: 300000 | E25: =D25/C25 -> 1.06406
A26: 시중노임은 대한건설협회 2026년 상반기 적용 건설업 임금실태조사 보고서(2026.1.1 적용) 기준. 대한건설협회 2026년 하반기 적용 조사(2026.9.1 적용) 132개 직종 평균 282,737원, 직전 대비 +0.98%. 적용 단가는 숙련 기능공 현장 실거래 수준(사용자 지시)으로 시중노임보다 높게 적용함.
A28: 출처
A29: 시중노임 상반기 | B29: https://www.kmcca.or.kr/images/pegs/down_file/2026%EB%85%84%20%EC%83%81%EB%B0%98%EA%B8%B0%EC%A0%81%EC%9A%A9%20%EA%B1%B4%EC%84%A4%EC%97%85%20%EC%9E%84%EA%B8%88%EC%8B%A4%ED%83%9C%EC%A1%B0%EC%82%AC%20%EB%B3%B4%EA%B3%A0%EC%84%9C.pdf
A30: 시중노임 하반기 | B30: http://www.conslove.co.kr/news/articleView.html?idxno=89479
A31: 산재·고용보험 요율 | B31: https://www.kosca21.or.kr/km_board/upload/km_b_notice/1767346180_02.pdf
A32: 산업안전보건관리비 | B32: https://biz.newdaily.co.kr/site/data/html/2026/05/07/2026050700116.html
A33: 원가계산 제비율 | B33: https://04noti.com/construction-cost-ratio-guide/
A34: 2026 4대보험(연금·건강) | B34: https://calctools.co.kr/blog/daily-worker-insurance
A35: 화재감시자 기준 | B35: 산업안전보건기준에 관한 규칙 제241조의2
A37: 조사일 2026-10-12. 요율은 해마다 바뀌므로 계약 시점 고시로 재확인 필요함.
